Workbook

Sheet Sheet1
A2: Attrition | B2: Yes
A4: Department | B4: Count of Attrition | C4: Count of Attrition2 | D4: Sum of Attrition Rate = Attrition_Count / Headcount_Count
A5: Customer Support | B5: 12 | C5: 0.17142857 | D5: 0
A6: Engineering | B6: 8 | C6: 0.11428571 | D6: 0
A7: Finance | B7: 11 | C7: 0.15714286 | D7: 0
A8: HR | B8: 11 | C8: 0.15714286 | D8: 0
A9: Operations | B9: 11 | C9: 0.15714286 | D9: 0
A10: Sales | B10: 17 | C10: 0.24285714 | D10: 0
A11: Grand Total | B11: 70 | C11: 1 | D11: 0

Sheet Employee Data
A1: Employee ID | B1: Department | C1: Job Role | D1: Age | E1: Gender | F1: Tenure (Years) | G1: Tenure Band | H1: Salary Band | I1: Performance Rating | J1: OverTime | K1: Attrition | L1: Reason for Leaving | N1: Note: Tenure Band is a live formula column — this is what lets you drag a clean
A2: 1001 | B2: Sales | C2: Sales Lead | D2: 57 | E2: Female | F2: 2.7 | G2: =IF(F2<1,"0-1 yrs",IF(F2<3,"1-3 yrs",IF(F2<7,"3-7 yrs","7+ yrs"))) -> 1-3 yrs | H2: Medium | I2: 2 | J2: Yes | K2: Yes | L2: Management Issues | N2: categorical field into a PivotTable instead of grouping raw decimal years manually.
A3: 1002 | B3: Sales | C3: Sales Lead | D3: 24 | E3: Female | F3: 1 | G3: =IF(F3<1,"0-1 yrs",IF(F3<3,"1-3 yrs",IF(F3<7,"3-7 yrs","7+ yrs"))) -> 1-3 yrs | H3: Low | I3: 1 | J3: No | K3: Yes | L3: Compensation
A4: 1003 | B4: Sales | C4: Sales Rep | D4: 42 | E4: Female | F4: 0.6 | G4: =IF(F4<1,"0-1 yrs",IF(F4<3,"1-3 yrs",IF(F4<7,"3-7 yrs","7+ yrs"))) -> 0-1 yrs | H4: Medium | I4: 3 | J4: No | K4: No
A5: 1004 | B5: Sales | C5: Account Manager | D5: 27 | E5: Female | F5: 4.2 | G5: =IF(F5<1,"0-1 yrs",IF(F5<3,"1-3 yrs",IF(F5<7,"3-7 yrs","7+ yrs"))) -> 3-7 yrs | H5: Low | I5: 3 | J5: Yes | K5: Yes | L5: Management Issues
A6: 1005 | B6: Sales | C6: Sales Rep | D6: 22 | E6: Male | F6: 2.8 | G6: =IF(F6<1,"0-1 yrs",IF(F6<3,"1-3 yrs",IF(F6<7,"3-7 yrs","7+ yrs"))) -> 1-3 yrs | H6: Medium | I6: 3 | J6: No | K6: Yes | L6: Work-Life Balance
A7: 1006 | B7: Sales | C7: Sales Rep | D7: 43 | E7: Male | F7: 1 | G7: =IF(F7<1,"0-1 yrs",IF(F7<3,"1-3 yrs",IF(F7<7,"3-7 yrs","7+ yrs"))) -> 1-3 yrs | H7: Medium | I7: 3 | J7: No | K7: Yes | L7: Relocation
A8: 1007 | B8: Sales | C8: Sales Lead | D8: 34 | E8: Male | F8: 0.4 | G8: =IF(F8<1,"0-1 yrs",IF(F8<3,"1-3 yrs",IF(F8<7,"3-7 yrs","7+ yrs"))) -> 0-1 yrs | H8: Low | I8: 5 | J8: Yes | K8: Yes | L8: Relocation
A9: 1008 | B9: Sales | C9: Account Manager | D9: 58 | E9: Male | F9: 4.8 | G9: =IF(F9<1,"0-1 yrs",IF(F9<3,"1-3 yrs",IF(F9<7,"3-7 yrs","7+ yrs"))) -> 3-7 yrs | H9: Medium | I9: 2 | J9: Yes | K9: No
A10: 1009 | B10: Sales | C10: Account Manager | D10: 22 | E10: Female | F10: 1.9 | G10: =IF(F10<1,"0-1 yrs",IF(F10<3,"1-3 yrs",IF(F10<7,"3-7 yrs","7+ yrs"))) -> 1-3 yrs | H10: Low | I10: 2 | J10: No | K10: No
A11: 1010 | B11: Sales | C11: Account Manager | D11: 37 | E11: Male | F11: 2.3 | G11: =IF(F11<1,"0-1 yrs",IF(F11<3,"1-3 yrs",IF(F11<7,"3-7 yrs","7+ yrs"))) -> 1-3 yrs | H11: Medium | I11: 3 | J11: Yes | K11: Yes | L11: Work-Life Balance
A12: 1011 | B12: Sales | C12: Sales Lead | D12: 37 | E12: Female | F12: 0.3 | G12: =IF(F12<1,"0-1 yrs",IF(F12<3,"1-3 yrs",IF(F12<7,"3-7 yrs","7+ yrs"))) -> 0-1 yrs | H12: High | I12: 2 | J12: No | K12: No
A13: 1012 | B13: Sales | C13: Sales Rep | D13: 26 | E13: Female | F13: 2.8 | G13: =IF(F13<1,"0-1 yrs",IF(F13<3,"1-3 yrs",IF(F13<7,"3-7 yrs","7+ yrs"))) -> 1-3 yrs | H13: Low | I13: 3 | J13: Yes | K13: Yes | L13: Career Growth
A14: 1013 | B14: Sales | C14: Sales Rep | D14: 27 | E14: Female | F14: 1.9 | G14: =IF(F14<1,"0-1 yrs",IF(F14<3,"1-3 yrs",IF(F14<7,"3-7 yrs","7+ yrs"))) -> 1-3 yrs | H14: Medium | I14: 5 | J14: No | K14: Yes | L14: Work-Life Balance
A15: 1014 | B15: Sales | C15: Sales Rep | D15: 24 | E15: Male | F15: 0.6 | G15: =IF(F15<1,"0-1 yrs",IF(F15<3,"1-3 yrs",IF(F15<7,"3-7 yrs","7+ yrs"))) -> 0-1 yrs | H15: Low | I15: 4 | J15: No | K15: No
A16: 1015 | B16: Sales | C16: Sales Rep | D16: 30 | E16: Female | F16: 2.4 | G16: =IF(F16<1,"0-1 yrs",IF(F16<3,"1-3 yrs",IF(F16<7,"3-7 yrs","7+ yrs"))) -> 1-3 yrs | H16: High | I16: 4 | J16: No | K16: No
A17: 1016 | B17: Sales | C17: Account Manager | D17: 22 | E17: Male | F17: 7 | G17: =IF(F17<1,"0-1 yrs",IF(F17<3,"1-3 yrs",IF(F17<7,"3-7 yrs","7+ yrs"))) -> 7+ yrs | H17: High | I17: 4 | J17: No | K17: No
A18: 1017 | B18: Sales | C18: Sales Lead | D18: 56 | E18: Male | F18: 0.5 | G18: =IF(F18<1,"0-1 yrs",IF(F18<3,"1-3 yrs",IF(F18<7,"3-7 yrs","7+ yrs"))) -> 0-1 yrs | H18: Low | I18: 4 | J18: No | K18: Yes | L18: Better Offer
A19: 1018 | B19: Sales | C19: Account Manager | D19: 45 | E19: Female | F19: 2.2 | G19: =IF(F19<1,"0-1 yrs",IF(F19<3,"1-3 yrs",IF(F19<7,"3-7 yrs","7+ yrs"))) -> 1-3 yrs | H19: Medium | I19: 3 | J19: No | K19: Yes | L19: Management Issues
A20: 1019 | B20: Sales | C20: Account Manager | D20: 49 | E20: Male | F20: 0.9 | G20: =IF(F20<1,"0-1 yrs",IF(F20<3,"1-3 yrs",IF(F20<7,"3-7 yrs","7+ yrs"))) -> 0-1 yrs | H20: Medium | I20: 5 | J20: Yes | K20: Yes | L20: Work-Life Balance
A21: 1020 | B21: Sales | C21: Account Manager | D21: 32 | E21: Male | F21: 3.9 | G21: =IF(F21<1,"0-1 yrs",IF(F21<3,"1-3 yrs",IF(F21<7,"3-7 yrs","7+ yrs"))) -> 3-7 yrs | H21: Medium | I21: 4 | J21: No | K21: No
A22: 1021 | B22: Sales | C22: Account Manager | D22: 42 | E22: Male | F22: 1.6 | G22: =IF(F22<1,"0-1 yrs",IF(F22<3,"1-3 yrs",IF(F22<7,"3-7 yrs","7+ yrs"))) -> 1-3 yrs | H22: Low | I22: 4 | J22: Yes | K22: Yes | L22: Compensation
A23: 1022 | B23: Sales | C23: Sales Rep | D23: 34 | E23: Male | F23: 13.4 | G23: =IF(F23<1,"0-1 yrs",IF(F23<3,"1-3 yrs",IF(F23<7,"3-7 yrs","7+ yrs"))) -> 7+ yrs | H23: Medium | I23: 4 | J23: No | K23: No
A24: 1023 | B24: Sales | C24: Sales Lead | D24: 26 | E24: Male | F24: 2 | G24: =IF(F24<1,"0-1 yrs",IF(F24<3,"1-3 yrs",IF(F24<7,"3-7 yrs","7+ yrs"))) -> 1-3 yrs | H24: Low | I24: 3 | J24: No | K24: No
A25: 1024 | B25: Sales | C25: Sales Lead | D25: 55 | E25: Male | F25: 7.7 | G25: =IF(F25<1,"0-1 yrs",IF(F25<3,"1-3 yrs",IF(F25<7,"3-7 yrs","7+ yrs"))) -> 7+ yrs | H25: Medium | I25: 3 | J25: Yes | K25: No
A26: 1025 | B26: Sales | C26: Account Manager | D26: 22 | E26: Female | F26: 2.3 | G26: =IF(F26<1,"0-1 yrs",IF(F26<3,"1-3 yrs",IF(F26<7,"3-7 yrs","7+ yrs"))) -> 1-3 yrs | H26: Medium | I26: 3 | J26: No | K26: No
A27: 1026 | B27: Sales | C27: Account Manager | D27: 29 | E27: Male | F27: 9.5 | G27: =IF(F27<1,"0-1 yrs",IF(F27<3,"1-3 yrs",IF(F27<7,"3-7 yrs","7+ yrs"))) -> 7+ yrs | H27: Low | I27: 4 | J27: Yes | K27: No
A28: 1027 | B28: Sales | C28: Sales Rep | D28: 24 | E28: Female | F28: 0.3 | G28: =IF(F28<1,"0-1 yrs",IF(F28<3,"1-3 yrs",IF(F28<7,"3-7 yrs","7+ yrs"))) -> 0-1 yrs | H28: Medium | I28: 1 | J28: No | K28: Yes | L28: Career Growth
A29: 1028 | B29: Sales | C29: Account Manager | D29: 52 | E29: Male | F29: 2.8 | G29: =IF(F29<1,"0-1 yrs",IF(F29<3,"1-3 yrs",IF(F29<7,"3-7 yrs","7+ yrs"))) -> 1-3 yrs | H29: Medium | I29: 4 | J29: No | K29: No
A30: 1029 | B30: Sales | C30: Account Manager | D30: 57 | E30: Female | F30: 11.1 | G30: =IF(F30<1,"0-1 yrs",IF(F30<3,"1-3 yrs",IF(F30<7,"3-7 yrs","7+ yrs"))) -> 7+ yrs | H30: Low | I30: 3 | J30: No | K30: No
A31: 1030 | B31: Sales | C31: Sales Lead | D31: 35 | E31: Female | F31: 0.9 | G31: =IF(F31<1,"0-1 yrs",IF(F31<3,"1-3 yrs",IF(F31<7,"3-7 yrs","7+ yrs"))) -> 0-1 yrs | H31: Low | I31: 1 | J31: Yes | K31: Yes | L31: Better Offer
A32: 1031 | B32: Sales | C32: Sales Lead | D32: 55 | E32: Female | F32: 0.5 | G32: =IF(F32<1,"0-1 yrs",IF(F32<3,"1-3 yrs",IF(F32<7,"3-7 yrs","7+ yrs"))) -> 0-1 yrs | H32: Medium | I32: 5 | J32: No | K32: Yes | L32: Career Growth
A33: 1032 | B33: Sales | C33: Account Manager | D33: 52 | E33: Female | F33: 1.9 | G33: =IF(F33<1,"0-1 yrs",IF(F33<3,"1-3 yrs",IF(F33<7,"3-7 yrs","7+ yrs"))) -> 1-3 yrs | H33: Low | I33: 3 | J33: Yes | K33: Yes | L33: Management Issues
A34: 1033 | B34: Sales | C34: Sales Lead | D34: 23 | E34: Male | F34: 1.5 | G34: =IF(F34<1,"0-1 yrs",IF(F34<3,"1-3 yrs",IF(F34<7,"3-7 yrs","7+ yrs"))) -> 1-3 yrs | H34: Medium | I34: 3 | J34: No | K34: No
A35: 1034 | B35: Sales | C35: Sales Lead | D35: 38 | E35: Male | F35: 3.1 | G35: =IF(F35<1,"0-1 yrs",IF(F35<3,"1-3 yrs",IF(F35<7,"3-7 yrs","7+ yrs"))) -> 3-7 yrs | H35: Low | I35: 3 | J35: No | K35: No
A36: 1035 | B36: Sales | C36: Account Manager | D36: 55 | E36: Male | F36: 6.4 | G36: =IF(F36<1,"0-1 yrs",IF(F36<3,"1-3 yrs",IF(F36<7,"3-7 yrs","7+ yrs"))) -> 3-7 yrs | H36: High | I36: 3 | J36: Yes | K36: No
A37: 1036 | B37: Engineering | C37: QA Engineer | D37: 34 | E37: Male | F37: 0.1 | G37: =IF(F37<1,"0-1 yrs",IF(F37<3,"1-3 yrs",IF(F37<7,"3-7 yrs","7+ yrs"))) -> 0-1 yrs | H37: Medium | I37: 4 | J37: Yes | K37: No
A38: 1037 | B38: Engineering | C38: DevOps Engineer | D38: 23 | E38: Male | F38: 0.2 | G38: =IF(F38<1,"0-1 yrs",IF(F38<3,"1-3 yrs",IF(F38<7,"3-7 yrs","7+ yrs"))) -> 0-1 yrs | H38: Medium | I38: 3 | J38: No | K38: No
A39: 1038 | B39: Engineering | C39: Software Engineer | D39: 26 | E39: Female | F39: 1.1 | G39: =IF(F39<1,"0-1 yrs",IF(F39<3,"1-3 yrs",IF(F39<7,"3-7 yrs","7+ yrs"))) -> 1-3 yrs | H39: Low | I39: 2 | J39: Yes | K39: Yes | L39: Work-Life Balance
A40: 1039 | B40: Engineering | C40: QA Engineer | D40: 28 | E40: Male | F40: 2.4 | G40: =IF(F40<1,"0-1 yrs",IF(F40<3,"1-3 yrs",IF(F40<7,"3-7 yrs","7+ yrs"))) -> 1-3 yrs | H40: Medium | I40: 3 | J40: No | K40: Yes | L40: Management Issues
...

Sheet Answer Key
A1: Expected PivotTable Results (Answer Key)
A2: Built independently with COUNTIFS — use this to verify your PivotTable numbers match.
A4: Attrition Rate by Department
A5: Department | B5: Headcount | C5: Left | D5: Attrition Rate
A6: Customer Support | B6: =COUNTIF('Employee Data'!$B$2:$B$197,$A6) -> 31 | C6: =COUNTIFS('Employee Data'!$B$2:$B$197,$A6,'Employee Data'!$K$2:$K$197,"Yes") -> 12 | D6: =IFERROR(C6/B6,0) -> 0.38709677
A7: Engineering | B7: =COUNTIF('Employee Data'!$B$2:$B$197,$A7) -> 31 | C7: =COUNTIFS('Employee Data'!$B$2:$B$197,$A7,'Employee Data'!$K$2:$K$197,"Yes") -> 8 | D7: =IFERROR(C7/B7,0) -> 0.25806452
A8: Finance | B8: =COUNTIF('Employee Data'!$B$2:$B$197,$A8) -> 30 | C8: =COUNTIFS('Employee Data'!$B$2:$B$197,$A8,'Employee Data'!$K$2:$K$197,"Yes") -> 11 | D8: =IFERROR(C8/B8,0) -> 0.36666667
A9: HR | B9: =COUNTIF('Employee Data'!$B$2:$B$197,$A9) -> 29 | C9: =COUNTIFS('Employee Data'!$B$2:$B$197,$A9,'Employee Data'!$K$2:$K$197,"Yes") -> 11 | D9: =IFERROR(C9/B9,0) -> 0.37931034
A10: Operations | B10: =COUNTIF('Employee Data'!$B$2:$B$197,$A10) -> 40 | C10: =COUNTIFS('Employee Data'!$B$2:$B$197,$A10,'Employee Data'!$K$2:$K$197,"Yes") -> 11 | D10: =IFERROR(C10/B10,0) -> 0.275
A11: Sales | B11: =COUNTIF('Employee Data'!$B$2:$B$197,$A11) -> 35 | C11: =COUNTIFS('Employee Data'!$B$2:$B$197,$A11,'Employee Data'!$K$2:$K$197,"Yes") -> 17 | D11: =IFERROR(C11/B11,0) -> 0.48571429
A14: Attrition Rate by Tenure Band
A15: Tenure Band | B15: Headcount | C15: Left | D15: Attrition Rate
A16: 0-1 yrs | B16: =COUNTIF('Employee Data'!$G$2:$G$197,$A16) -> 61 | C16: =COUNTIFS('Employee Data'!$G$2:$G$197,$A16,'Employee Data'!$K$2:$K$197,"Yes") -> 30 | D16: =IFERROR(C16/B16,0) -> 0.49180328
A17: 1-3 yrs | B17: =COUNTIF('Employee Data'!$G$2:$G$197,$A17) -> 57 | C17: =COUNTIFS('Employee Data'!$G$2:$G$197,$A17,'Employee Data'!$K$2:$K$197,"Yes") -> 26 | D17: =IFERROR(C17/B17,0) -> 0.45614035
A18: 3-7 yrs | B18: =COUNTIF('Employee Data'!$G$2:$G$197,$A18) -> 49 | C18: =COUNTIFS('Employee Data'!$G$2:$G$197,$A18,'Employee Data'!$K$2:$K$197,"Yes") -> 10 | D18: =IFERROR(C18/B18,0) -> 0.20408163
A19: 7+ yrs | B19: =COUNTIF('Employee Data'!$G$2:$G$197,$A19) -> 29 | C19: =COUNTIFS('Employee Data'!$G$2:$G$197,$A19,'Employee Data'!$K$2:$K$197,"Yes") -> 4 | D19: =IFERROR(C19/B19,0) -> 0.13793103
A22: Attrition Rate by OverTime Status
A23: OverTime | B23: Headcount | C23: Left | D23: Attrition Rate
A24: Yes | B24: =COUNTIF('Employee Data'!$J$2:$J$197,$A24) -> 75 | C24: =COUNTIFS('Employee Data'!$J$2:$J$197,$A24,'Employee Data'!$K$2:$K$197,"Yes") -> 32 | D24: =IFERROR(C24/B24,0) -> 0.42666667
A25: No | B25: =COUNTIF('Employee Data'!$J$2:$J$197,$A25) -> 121 | C25: =COUNTIFS('Employee Data'!$J$2:$J$197,$A25,'Employee Data'!$K$2:$K$197,"Yes") -> 38 | D25: =IFERROR(C25/B25,0) -> 0.31404959
